Workbook

Sheet Sheet1
B1: Topic | C1: Count | D1: Name | E1: Representation | F1: Representative_Docs | G1: GPT Label | H1: Better Label? | I1: Category (0 - Background, 1 - Oon before, 2 - Trigger, 3 - Oon after) | J1: Remarks
A2: 0 | B2: 1 | C2: 3225 | D2: 1_mom back_want mom_mom mom_mum | E2: ['mom back', 'want mom', 'mom mom', 'mum', 'love mom', 'relationship mom', 'miss', 'mom always', 'mom want', 'like mom'] | F2: ['I just want my mom back.', 'I want my mom back.', 'I just want my mom back.', 'I just want my mom back.', 'Seriously I want my mom back.'] | G2: Desire for Reconnection with Mother | J2: Narr's needs
A3: 1 | B3: 3 | C3: 2615 | D3: 3_dad dad_love dad_dad always_like dad | E3: ['dad dad', 'love dad', 'dad always', 'like dad', 'miss', 'stepdad', 'know dad', 'dad would', 'dad never', 'step dad'] | F3: ['My dad was always easier.', 'My dad and I have always had a rocky relationship.', 'I love my dad but this is tough to say the least.', 'Despite everything, I love my dad and can‚Äôt help but mourn the childhood I spent with him.', 'I love my dad a lot.'] | G3: Strained Father-Child Relationships Due to QAnon | I3: 3-Oon after-Social
A4: 2 | B4: 4 | C4: 2572 | D4: 4_text_screamed_mad_hung | E4: ['text', 'screamed', 'mad', 'hung', 'argue', 'texted', 'answer', 'stop talking', 'want talk', 'upset'] | F4: ['He asks a lot of questions and I just try to answer them or look them up with him.', 'He started screaming at me, I told him not to raise his fucking voice at me while I‚Äôm trying to have a convo with him and hung up.', 'I was hyperventilating and crying uncontrollably and he interpreted it as me trying to scare him like I was mad or something so he just yelled louder until he left eventually.', 'He‚Äôll discuss it, but he gets pretty upset if you actually bring up good points.', "He knows I don't want to hear it, but he likes making me mad."] | G4: Family Conflict Over QAnon Beliefs | H4: Q's Hostile Behavior towards others | I4: 3-Oon after-Behavior/action
A5: 3 | B5: 5 | C5: 1981 | D5: 5_text_argue_spoken_want talk | E5: ['text', 'argue', 'spoken', 'want talk', 'hung', 'texting', 'answer', 'thanked', 'talk anymore', 'disagree'] | F5: ["I haven't spoken to her since then and it's been about a month.", 'She just want to agree to disagree, I want to discuss the matter, understand her reasoning... so in the end we just agree to disagree.', "Who's going to argue with her?", 'I have yet to text her back.', "I didn't see the text so she called."] | G5: Family Communication Breakdown Due to QAnon Beliefs | I5: 3-Oon after-Behavior/action
A6: 4 | B6: 13 | C6: 1121 | D6: 13_doctor_doctors_cancer_hospital | E6: ['doctor', 'doctors', 'cancer', 'hospital', 'medical', 'meds', 'medicine', 'medication', 'cure', 'treatment'] | F6: ['(Give her cancer or something).', 'Not to mention SHE IS A DOCTOR!!!', 'I urged her to get to her doctor.', 'You cannot just look at her and say she‚Äôs not a doctor.', "She is the hospital right now, and I don't how long she's had the cancer yet."] | G6: Family Impact of Medical Misinformation in QAnon Context | H6: Distrust in doctors? | I6: 3-Oon after-Behavior/action
A7: 5 | B7: 20 | C7: 850 | D7: 20_oxygen_hospital_doctor_doctors | E7: ['oxygen', 'hospital', 'doctor', 'doctors', 'medical', 'heart attack', 'diabetes', 'medication', 'cancer', 'failure'] | F7: ['He is over 70 and has diabetes, high blood pressure, and congestive heart failure.', 'His wife has been sick and is now in hospital.', 'And after evaluating him they decided to bring him to a mental hospital.', 'After getting out of the hospital.. he was not the same.', 'His blood oxygen when he made it to the ER was 76.'] | G7: Health and Medical Issues Related to QAnon Beliefs | H7: Related to QAnon Beliefs | I7: 0-Background-Health
A8: 6 | B8: 29 | C8: 630 | D8: 29_sisters_siblings_brothers_older | E8: ['sisters', 'siblings', 'brothers', 'older', 'little sister', 'older sister', 'told brother', 'younger', 'niece', 'younger sister'] | F8: ['Two of my older sisters feel the same way more or less.', "My older sister has begun to just ignore my mom, while my little sister (who has autism) is very upset that she can't make my mom understand she's being ridiculous.", 'i talked to my older sister about this too.', 'We were closer sisters than me and my blood sister.', 'She is mad at me and my 2 sisters.'] | G8: Family Dynamics and QAnon Influence on Sibling Relationships | H8: QAnon Influence on Family Dynamics (Sibling Relationships) | I8: 3-Oon after-Impact to others
A9: 7 | B9: 31 | C9: 618 | D9: 31_drops_believer_related_full blown | E9: ['drops', 'believer', 'related', 'full blown', 'blown', 'er', 'followers', 'anonymous', 'believers', 'discovered'] | F9: ['He is a stout Q believer.', "I look through his posts, he's full blown Q guy, Trump is the savior, the whole thing.", 'He pretty quickly became a full blown q convert and stopped going into work more and more often so he could spend more time watching youtube and talking to other fellow believers.', 'Sorry for the rant..... anyway......\n\nNot only was everyone I was watching talking about "Q Drops"...but they were also all becoming..............extremely fond of Trump.', 'he calls Q drops and the videos from top Q believers on youtube the "new Bible" and tells me to throw my copies of the "old" one away.'] | G9: QAnon Belief and Influence on Personal Lives | H9: Full-blown stage into Q?
A10: 8 | B10: 34 | C10: 569 | D10: 34_daughter_rest family_parent_side family | E10: ['daughter', 'rest family', 'parent', 'side family', 'family really', 'kid', 'grandparent', 'people family', 'son', 'sees'] | F10: ['But it kills me knowing that the rest of my family has to deal with him.', 'The rest of my family wouldn‚Äôt engage the subject at all with him.', "i don't know what to do or how to be his daughter anymore.", "I'm his daughter, his only child.", 'What do I say to demonstrate that he should put his daughter first, above all of this crap??'] | G10: Family Struggles with QAnon Beliefs | H10: QAnon Influence on Family Dynamics | I10: 3-Oon after-Impact to others
A11: 9 | B11: 35 | C11: 556 | D11: 35_boyfriend_hes_cheated_divorce | E11: ['boyfriend', 'hes', 'cheated', 'divorce', 'dare', 'agrees', 'dating', 'lets', 'ex', 'goes along'] | F11: ["It started with him threatening to dox and expose her, but then it moved to threatening to harm her, her boyfriend and even her boyfriend's cat if she didn't come back to him.", 'I don‚Äôt think he agrees with her beliefs but he just kind of lets it happen.', "Then she met her boyfriend, let's call him Dave.", '(The TL;DR of that is she had a boyfriend but cheated on that guy with my friend, but I again veer into other topics).', 'Her base for divorce was \'Hes not awake, hes part of the cabal, hes keeping secrets from me, hes gay"....'] | G11: Relationship Strain Due to QAnon Beliefs | H11: ??? | I11: 0-Background-Partner
A12: 10 | B12: 39 | C12: 523 | D12: 39_insanity_crazy one_madness_sane | E12: ['insanity', 'crazy one', 'madness', 'sane', 'sanity', 'craziness', 'like crazy', 'think crazy', 'going crazy', 'going insane'] | F12: ['I feel like I‚Äôm the crazy one.', "I don't think I have it in me to deal with any more of this insanity.", 'The man lost *everything* to this insanity.', "I'm so sick of the insanity.", 'When does this insanity end?'] | G12: Family Struggles with QAnon-Induced Insanity | H12: Family Struggles
A13: 11 | B13: 40 | C13: 523 | D13: 40_missing_saving children_protect_saving | E13: ['missing', 'saving children', 'protect', 'saving', 'safety', 'kid', 'save children', 'abuse', 'kids want', 'child abuse'] | F13: ['The estrangements were painful for these parents and in an attempt to help them process what was happening, the essay author noticed a trend of ‚Äúmissing missing reasons.‚Äù TL;DR these estranged parents almost uniformly were unable to say why they had been cut off by their adult children.', 'I am so frustrated with this "missing children" crap.', 'In many countries, statistics on missing children are not even available; and, unfortunately, even available statistics may be inaccurate due to: under-reporting/under-recognition; inflation; incorrect database entry of case information; and deletion of records once a case is closed.‚Äù \n\nand also\n\n ‚Äú250,000 children are reported missing every year in the EU, 1 child every 2 minutes‚Äù\n\ni know that the vast majority of these reported cases are custody disputes between estranged parents, but he is completely sold that these kids are legitimately abducted and trafficked, despite that being an absolutely insane number, and wouldn‚Äôt that constitute the biggest news story of our times!?', 'You thought you were saving children?', 'And where the hell are all the missing migrant children?!?!?!?!?!'] | G13: Concerns about Missing and Abducted Children | H13: Q's Belief "Save the Children" | I13: 3-Oon after-Belief
A14: 12 | B14: 42 | C14: 496 | D14: 42_relationships_strained_end relationship_repair | E14: ['relationships', 'strained', 'end relationship', 'repair', 'good relationship', 'strain relationship', 'strain', 'surface level', 'time together', 'complicated'] | F14: ['Things have been strained between the two of us since.', "In other words, it's time for me to triage my relationships.", 'I had been in several dysfunctional relationships but this was the worst.', 'Sometimes those relationships can be mended; sometimes they can‚Äôt be.', 'Suffice it to say the relationships are very strained.'] | G14: Strained Relationships Due to QAnon Involvement | I14: 3-Oon after-Social
A15: 13 | B15: 43 | C15: 493 | D15: 43_black_racist_white_racism | E15: ['black', 'racist', 'white', 'racism', 'black people', 'white people', 'race', 'brown', 'supremacy', 'color'] | F15: ['One of the things growing up that we both really struggled with was race and how having a white mother and black father was being too white for the black kids and too black for the white kids.', 'My boyfriend is black, his friend is white, and I am also white.', 'I am a black woman and my husband is a white man from the Midwest.', 'Im in a multiracial family, and often grapple with the fact that my father can be so racist when he has a black son and wife.', 'As far as racism goes everyone in the world is racist in some way.'] | G15: Interracial Relationships and Racism Experiences | I15: 0-Background-Race
A16: 14 | B16: 44 | C16: 484 | D16: 44_conversations_spoken_spoken since_communication | E16: ['conversations', 'spoken', 'spoken since', 'communication', 'end conversation', 'want talk', 'talk phone', 'talk anything', 'conversation went', 'small talk'] | F16: ['We‚Äôve had many of these conversations.', 'We were able to have real conversations.', 'Any conversations we have can be kept confidential for now.', 'We do not talk often so it never comes up in our conversations.', 'Our conversations were only about this.'] | G16: Communication Challenges in Conversations | H16: ??? | I16: ???
A17: 15 | B17: 45 | C17: 474 | D17: 45_ivermectin_horse_cure_paste | E17: ['ivermectin', 'horse', 'cure', 'paste', 'doctor', 'treat', 'doctors', 'medicine', 'doses', 'ordered'] | F17: ['and they with their buckets of ivermectin dgaf then, so why does it matter now?).', 'I have a question about ivermectin.', 'I said, "No, I won\'t be taking ivermectin.', "Ivermectin and hydroxychloroquine aren't working.", 'What effectiveness had ivermectin had anyway?'] | G17: Ivermectin Use and Skepticism in Treating Illness | I17: 3-Oon after-Belief
A18: 16 | B18: 50 | C18: 445 | D18: 50_currency_gold_silver_crypto | E18: ['currency', 'gold', 'silver', 'crypto', 'scam', 'debt', 'bank', 'dollar', 'banks', 'worthless'] | F18: ["He's been slowly funneling out our money to crypto currency that I don't have access to.", 'Thankfully he just bought gold and silver with it though.', 'My mom is spending hers and my dads life savings on crypto currency and also buying all sorts of worthless currency from EBay (Zimbabwe, Iraqi, Venezuelan currency).', 'Then somehow it turns into how we aren‚Äôt aware of what‚Äôs happening in this country and how currency is about to change to gold and silver and demanded that tomorrow he is going to buy gold!', 'He wants to put all our money into gold/silver purchases.'] | G18: Financial Decisions Influenced by Conspiracy Beliefs | I18: 3-Oon after-Behavior/action
A19: 17 | B19: 51 | C19: 443 | D19: 51_christmas_thanksgiving_holidays_holiday | E19: ['christmas', 'thanksgiving', 'holidays', 'holiday', 'celebrate', 'easter', 'eve', 'xmas', 'season', 'home christmas'] | F19: ['Christmas is just going to be different through and through.', 'I‚Äôm honestly thinking about skipping Christmas.', 'Most of my family spent Christmas day together.', 'Our Christmas traditions won‚Äôt be the same.', 'We usually spend Thanksgiving and Christmas with my family but not this year.'] | G19: Family Holiday Gatherings Affected by QAnon | I19: 3-Oon after-Impact to others
A20: 18 | B20: 52 | C20: 440 | D20: 52_step dad_told dad_step_even dad | E20: ['step dad', 'told dad', 'step', 'even dad', 'divorce', 'dad said', 'dad would', 'dad told', 'dad thinks', 'divorced'] | F20: ['She has threatened to divorce my dad after nearly 20 years of marriage because he expressed concern in her habits and behavior.', '(It at least makes me feel better that even my dad needed to see her freak out like this to realize how deep the manipulation went, and he was married to her for over 20 years before they divorced when I was in high school.', "she also said she couldnt text about it, could only talk on the phone wtf\n\ni texted my step dad saying i didn't appreciate her threatening me and to knock it off!", 'I told my dad (her son) that she hasn‚Äôt had an original thought for a long time because my step-grandpa won‚Äôt let her.', 'I am afraid she will lose my step dad.'] | G20: Family Strain Due to QAnon Beliefs | H20: (Stepdad) / manipulation | I20: 3-Oon after-Behavior/action
A21: 19 | B21: 53 | C21: 437 | D21: 53_weed_drugs_mental health_bipolar | E21: ['weed', 'drugs', 'mental health', 'bipolar', 'depression', 'addict', 'drug', 'drinking', 'schizophrenia', 'alcohol'] | F21: ["This is the same man that grew weed in our house growing up because then Government can't tell him what to do.", 'Keep in mind this person was outgoing and rebellious as a kid but growing up and after making poor decisions, from smoking weed to then more hard drugs such as meth, they‚Äôve became very different.', 'He has very strong anxiety and smokes a lot of weed.', 'Dmt, shrooms, weed, etc, should be stopped.', 'Also, he was not just on weed.'] | G21: Substance Use and Mental Health Issues | I21: 0-Background-Substance Use
A22: 20 | B22: 54 | C22: 427 | D22: 54_want kids_whole family_rest family_grandchild | E22: ['want kids', 'whole family', 'rest family', 'grandchild', 'son', 'extended family', 'see kids', 'family members', 'much family', 'contact family'] | F22: ["I swear she quotes all of the speaker's she sees I agreed with her and said I didn't want my kids to grow up with that outlook.", 'When she asked what kind of things I said things like who you want your kids to go to and medical things like a DNR.', 'She is in deep and says her whole family is as well.', "I've tried so hard to have a relationship with her for the sake of my kid, her own grandchild, because I know how much she loves him.", "She's estranged to the whole family, and I'm basically the only link I have from her to the rest of the family."] | G22: Family Estrangement Due to QAnon Beliefs | I22: 3-Oon after-Impact to others
A23: 21 | B23: 55 | C23: 412 | D23: 55_therapy_therapist_counseling_therapists | E23: ['therapy', 'therapist', 'counseling', 'therapists', 'couples', 'counselor', 'appointment', 'session', 'sessions', 'insurance'] | F23: ['And I‚Äôm still in therapy.', 'I have done the most therapy(by far).', 'I‚Äôm working on it with therapy.', "I've been through years of therapy.", 'I have recently been going to therapy to deal with these issues.'] | G23: Coping with QAnon-Related Family Strain through Therapy | I23: 3-Oon after-Impact to narr
A24: 22 | B24: 56 | C24: 405 | D24: 56_arguments_arguing_argue_argument | E24: ['arguments', 'arguing', 'argue', 'argument', 'debate', 'disagree', 'agree disagree', 'civil', 'debating', 'argued'] | F24: ["These weren't the only arguments we had about this, there was more.", "We've had these arguments already.", "We've never gotten into more arguments.", 'YOU TAKE ALL MY ARGUMENTS!', "Since then we've been fine, no arguments or anything at all."] | G24: Family Disputes Over QAnon Beliefs | H24: Family Arguments Over QAnon Beliefs | I24: 3-Oon after-Behavior/action
A25: 23 | B25: 58 | C25: 396 | D25: 58_mum_help mom_told mom_mom says | E25: ['mum', 'help mom', 'told mom', 'mom says', 'mom goes', 'get mom', 'agrees', 'mom mom', 'mom like', 'mom always'] | F25: ['Sometimes I just think about if his need for a car/help for his mom wasn‚Äôt in the picture, would he have stretched that timeframe of not wanting to be around me further?', 'I told my mom and she said he refuses to apologize since he was "tired when he said it".', 'We got passed him not wanting to see me because I am ‚Äúshedding‚Äù but a part of me believes that he only let me back in (being physically around him) because he needed help with his elderly mother (and not having car to help with his mom).', 'I am trying to help him and my mom to get into counseling for resolving there past conflict and become more open to one another.', 'He needed help with mom.'] | G25: Family Dynamics and Support Involving Mom | H25: ??? | I25: ???
A26: 24 | B26: 59 | C26: 394 | D26: 59_miss_love much_still love_feel bad | E26: ['miss', 'love much', 'still love', 'feel bad', 'senses', 'loves', 'want relationship', 'person used', 'come back', 'get back'] | F26: ['I want him to miss me too.', 'I miss him more than anything.', 'I just miss him so very, very much!', 'I miss him so much.', 'I just miss him and wish it wasn‚Äôt like this.'] | G26: Missing Loved Ones Due to QAnon Involvement | I26: 3-Oon after-Impact to narr
A27: 25 | B27: 60 | C27: 394 | D27: 60_cried_cry_crying_tears | E27: ['cried', 'cry', 'crying', 'tears', 'scream', 'sobbing', 'laugh', 'void', 'eyes', 'broke'] | F27: ['I cried because of how happy I was.', 'I cried so much already.', 'Maybe I cried all I could that day in the barn.', 'I cried, I was angry, I had so much sorrow, and I grieved.', 'I have cried so many tears and am on anti depressants to help me out.'] | G27: Emotional Distress and Coping | I27: 3-Oon after-Impact to narr
A28: 26 | B28: 64 | C28: 363 | D28: 64_older brother_brothers_older_younger brother | E28: ['older brother', 'brothers', 'older', 'younger brother', 'brother said', 'like brother', 'little brother', 'younger', 'brother told', 'lose'] | F28: ['My older brother has always walked on water in my eyes.', "I MISS MY OLDER BROTHER WHO I WISHED TO BE AS COOL AS GROWING UP BUT NOW I DON'T EVEN RECOGNIZE YOU.", 'My brothers are the same.', 'Both of my brothers have done this, it‚Äôs my turn.', 'My older brother was so special to us (lost him \\~7 years ago).'] | G28: Family Strain Due to QAnon Beliefs | H28: (Narrator-oon) Relationship with Brother? | I28: 0-Background-Relationship with narr
A29: 27 | B29: 66 | C29: 353 | D29: 66_twitter_facebook_fb_banned | E29: ['twitter', 'facebook', 'fb', 'banned', 'social media', 'account', 'https twitter', 'https twitter com', 'twitter com', 'instagram'] | F29: ['The best way to keep up on happenings is with these Twitter accounts:\n\n&#x200B;\n\n[https://twitter.com/fr\\_brennan](https://twitter.com/fr_brennan)\n\n[https://twitter.com/Kirtaner](https://twitter.com/Kirtaner)\n\n[https://twitter.com/AJVicens](https://twitter.com/AJVicens)\n\n[https://twitter.com/alibreland](https://twitter.com/alibreland)\n\n[https://twitter.com/AmericanHacker](https://twitter.com/AmericanHacker)\n\n[https://twitter.com/FoucaultMotoko](https://twitter.com/FoucaultMotoko)', 'He‚Äôs more active on twitter than fb.', "I looked down at my phone for something and saw the announcement that Trump's twitter account had been banned.", 'His Twitter account got banned a day before trump‚Äôs did.', 'I ask him to give up twitter (for a few days) and he can‚Äôt do that.'] | G29: Social Media and QAnon Involvement | I29: 2-Trigger-Social Media
A30: 28 | B30: 69 | C30: 345 | D30: 69_boundaries_bring back_like lost_want back | E30: ['boundaries', 'bring back', 'like lost', 'want back', 'breaks heart', 'feel like lost', 'want lose', 'breaks', 'get back', 'love much'] | F30: ['I feel like I lost her.', 'I feel like I lost her.', "I feel like she's lost to me.", 'he backed me up in my boundaries because he also has those boundaries with her, And is definitely the only reason why she is adhering to those boundaries right now.', 'She won‚Äôt adhere to my boundaries.'] | G30: Family Strain Due to QAnon Beliefs | I30: 3-Oon after-Impact to narr | J30: Narr's feeling
A31: 30 | B31: 73 | C31: 329 | D31: 73_youtube_algorithm_podcast_youtube videos | E31: ['youtube', 'algorithm', 'podcast', 'youtube videos', 'channel', 'algorithms', 'youtube com', 'youtube video', 'https', 'videos articles'] | F31: [' \n\nHello everyone,\n\nmy Name is Adrian and I am a journalist, working for the german television broadcast SPIEGEL TV MAGAZIN (Our YT-Channel: [https://www.youtube.com/user/spiegeltv](https://www.youtube.com/user/spiegeltv)).', 'Another interesting video I found on youtube is this one: [https://www.youtube.com/watch?v=NPHwO\\_sVSAQ](https://www.youtube.com/watch?v=NPHwO_sVSAQ).', 'I didn‚Äôt click on the YouTube video he sent because I didn‚Äôt want the algorithm to think I was interested in that.', 'But a lot comes from YouTube.', 'His youtube algorithm is nothing but this stuff.'] | G31: Impact of YouTube Algorithms on QAnon Content Consumption | I31: 2-Trigger-Social Media
A32: 31 | B32: 74 | C32: 327 | D32: 74_grief_grieving_mourning_grieve | E32: ['grief', 'grieving', 'mourning', 'grieve', 'betrayed', 'loss', 'like mourning', 'still alive', 'mourn', 'alive'] | F32: ['I felt the grief again.', "It feels like I'm grieving for someone who is still alive.", 'It feels like grieving a loss.', 'We are literally grieving the loss of our loved ones while they are still alive.', "I've honestly felt grief at the loss."] | G32: Grieving the Living | I32: 3-Oon after-Impact to narr
A33: 32 | B33: 78 | C33: 311 | D33: 78_pandemic_pandemic started_pandemic hit_since pandemic | E33: ['pandemic', 'pandemic started', 'pandemic hit', 'since pandemic', 'start pandemic', 'hit', 'pandemic really', 'pandemic began', 'beginning pandemic', 'got worse'] | F33: ["I'm frigging sick of this pandemic.", 'I hate what this pandemic has done to my kids‚Äô lives.', 'And then the pandemic happened.', "With the pandemic, it's been worse.", 'All well before the pandemic.'] | G33: Impact of the Pandemic on Personal Lives | I33: 2-Trigger-Pandemic
A34: 33 | B34: 81 | C34: 307 | D34: 81_baby_pregnant_pregnancy_first child | E34: ['baby', 'pregnant', 'pregnancy', 'first child', 'newborn', 'birth', 'born', 'expecting', 'grandchild', 'daughter'] | F34: ['How does anyone do this to their baby?!', 'We are having a baby soon.', "I kissed my baby's forehead and left.", 'I was just worried about my baby.', "Or, let's make love and make a baby."] | G34: Family and Pregnancy Concerns in QAnon Context | I34: 0-Background-Family
A35: 34 | B35: 83 | C35: 303 | D35: 83_retirement_lost job_fired_business | E35: ['retirement', 'lost job', 'fired', 'business', 'company', 'works', 'get job', 'retired', 'jobs', 'unemployed'] | F35: ['He hasnt lost his job yet, but it may happen.', 'Once he got to the U.S he worked a few odd jobs and started his own business.', 'They are maxed again and he is running out of retirement.', "He's a man nearing retirement age with a family.", 'He, the fucker, who‚Äôs close to retirement age anyway.'] | G35: Impact of QAnon on Employment and Retirement | H35: Impact of QAnon on | I35: 0-Background-Job
A36: 35 | B36: 86 | C36: 295 | D36: 86_sources_article_articles_source | E36: ['sources', 'article', 'articles', 'source', 'credible', 'reliable', 'proof', 'send', 'fake news', 'google'] | F36: ["I've sent her so many sources counteracting her and my uncle's claims.", 'I easily found multiple articles for each of her sources that debunked the information claimed and showed why these sources were not credible.', 'I asked her what sources she would trust.', 'I ask for sources and there is never any real source to back up the claims, but I "have to understand, she is getting this information from credible sources."', 'She won\'t listen to any fact, only these "sources".'] | G36: Credibility of Information Sources | H36: Q's unsourced belief? | I36: 3-Oon after-Behavior/action
A37: 36 | B37: 91 | C37: 279 | D37: 91_gates_bill gates_bill_5g | E37: ['gates', 'bill gates', 'bill', '5g', 'microchips', 'microchip', 'dna', 'vaccines', 'kill', 'population'] | F37: ['* Bill Gates - eugenics, decreasing the population, and vaccines\n* Globalism/NWO - George Soros, the Rockefellers, Jeff Bezos, Bill Gates, Klaus Schwabb, etc.', "And it was Bill Gates' company.", 'And of course the 5G, Covid, and Bill Gates conspiracies make sense to them.', 'Bill Gates is trying to implant microchips.', "I honestly still don't understand the Bill Gates thing."] | G37: Bill Gates and Conspiracy Theories | I37: 3-Oon after-Belief
A38: 37 | B38: 92 | C38: 276 | D38: 92_red_texas_florida_area | E38: ['red', 'texas', 'florida', 'area', 'rural', 'town', 'county', 'city', 'states', 'blue'] | F38: ['We live in a red state.', "We're also in a red state.", 'Still, he is deep in a red state.', 'We are from a very small rural red town.', 'I live in a very red area.'] | G38: Impact of QAnon in Conservative Rural Areas | H38: Demographics (red state) | I38: 0-Background-Political region
A39: 38 | B39: 99 | C39: 258 | D39: 99_racist_white_black_black people | E39: ['racist', 'white', 'black', 'black people', 'racism', 'race', 'racial', 'white supremacists', 'supremacists', 'white people'] | F39: ['He told me not to be racist.', 'That Trump is not now, nor has he ever been racist.', 'He is racist and he knows it.', 'It made him more racist.', 'He‚Äôs been doing this and making racist stereotypes.'] | G39: Racism and Racial Attitudes in QAnon Narratives | I39: 3-Oon after-Behavior/action
A40: 39 | B40: 100 | C40: 254 | D40: 100_anxiety_ocd_panic_panic attacks | E40: ['anxiety', 'ocd', 'panic', 'panic attacks', 'panic attack', 'attacks', 'attack', 'disorder', 'roof', 'depression'] | F40: ['Saying it was an anxiety attack.', 'Anxiety and panic attacks can mimic serious health issues which is compounding my fear.', 'I have an anxiety disorder and ocd.', 'I kept having panic attacks and my anxiety was so bad.', "Which I still haven't gotten myself to do because of the anxiety around it."] | G40: Anxiety and Panic Disorders | I40: 3-Oon after-Impact to narr
...

Sheet topics_merged
B1: (Color coded: Green = OK, Pink = So-so, can be better, Orange = Needs refinement, White = Not sure if we want to keep / what label to give
B2: Topic | C2: Count | D2: Name | E2: Representation | F2: Representative_Docs | G2: GPT Label | H2: Better Label? | I2: Category (0 - Background, 1 - Oon before, 2 - Trigger, 3 - Oon after) | J2: Remarks
A3: 0 | B3: 1 | C3: 3225 | D3: 1_mom back_want mom_mom mom_mum | E3: ['mom back', 'want mom', 'mom mom', 'mum', 'love mom', 'relationship mom', 'miss', 'mom always', 'mom want', 'like mom'] | F3: ['I just want my mom back.', 'I want my mom back.', 'I just want my mom back.', 'I just want my mom back.', 'Seriously I want my mom back.'] | G3: Desire for Reconnection with Mother | J3: Narr's needs
A4: 1 | B4: 3 | C4: 2615 | D4: 3_dad dad_love dad_dad always_like dad | E4: ['dad dad', 'love dad', 'dad always', 'like dad', 'miss', 'stepdad', 'know dad', 'dad would', 'dad never', 'step dad'] | F4: ['My dad was always easier.', 'My dad and I have always had a rocky relationship.', 'I love my dad but this is tough to say the least.', 'Despite everything, I love my dad and can‚Äôt help but mourn the childhood I spent with him.', 'I love my dad a lot.'] | G4: Strained Father-Child Relationships Due to QAnon | I4: 3-Oon after-Social
A5: 2 | B5: 4 | C5: 2572 | D5: 4_text_screamed_mad_hung | E5: ['text', 'screamed', 'mad', 'hung', 'argue', 'texted', 'answer', 'stop talking', 'want talk', 'upset'] | F5: ['He asks a lot of questions and I just try to answer them or look them up with him.', 'He started screaming at me, I told him not to raise his fucking voice at me while I‚Äôm trying to have a convo with him and hung up.', 'I was hyperventilating and crying uncontrollably and he interpreted it as me trying to scare him like I was mad or something so he just yelled louder until he left eventually.', 'He‚Äôll discuss it, but he gets pretty upset if you actually bring up good points.', "He knows I don't want to hear it, but he likes making me mad."] | G5: Family Conflict Over QAnon Beliefs | H5: Q's Hostile Behavior towards others | I5: 3-Oon after-Behavior/action
A6: 3 | B6: 5 | C6: 1981 | D6: 5_text_argue_spoken_want talk | E6: ['text', 'argue', 'spoken', 'want talk', 'hung', 'texting', 'answer', 'thanked', 'talk anymore', 'disagree'] | F6: ["I haven't spoken to her since then and it's been about a month.", 'She just want to agree to disagree, I want to discuss the matter, understand her reasoning... so in the end we just agree to disagree.', "Who's going to argue with her?", 'I have yet to text her back.', "I didn't see the text so she called."] | G6: Family Communication Breakdown Due to QAnon Beliefs | I6: 3-Oon after-Behavior/action
A7: 4 | B7: 13 | C7: 1121 | D7: 13_doctor_doctors_cancer_hospital | E7: ['doctor', 'doctors', 'cancer', 'hospital', 'medical', 'meds', 'medicine', 'medication', 'cure', 'treatment'] | F7: ['(Give her cancer or something).', 'Not to mention SHE IS A DOCTOR!!!', 'I urged her to get to her doctor.', 'You cannot just look at her and say she‚Äôs not a doctor.', "She is the hospital right now, and I don't how long she's had the cancer yet."] | G7: Family Impact of Medical Misinformation in QAnon Context | H7: Distrust in doctors? | I7: 3-Oon after-Behavior/action
A8: 5 | B8: 20 | C8: 850 | D8: 20_oxygen_hospital_doctor_doctors | E8: ['oxygen', 'hospital', 'doctor', 'doctors', 'medical', 'heart attack', 'diabetes', 'medication', 'cancer', 'failure'] | F8: ['He is over 70 and has diabetes, high blood pressure, and congestive heart failure.', 'His wife has been sick and is now in hospital.', 'And after evaluating him they decided to bring him to a mental hospital.', 'After getting out of the hospital.. he was not the same.', 'His blood oxygen when he made it to the ER was 76.'] | G8: Health and Medical Issues Related to QAnon Beliefs | H8: Related to QAnon Beliefs | I8: 0-Background-Health
A9: 6 | B9: 29 | C9: 630 | D9: 29_sisters_siblings_brothers_older | E9: ['sisters', 'siblings', 'brothers', 'older', 'little sister', 'older sister', 'told brother', 'younger', 'niece', 'younger sister'] | F9: ['Two of my older sisters feel the same way more or less.', "My older sister has begun to just ignore my mom, while my little sister (who has autism) is very upset that she can't make my mom understand she's being ridiculous.", 'i talked to my older sister about this too.', 'We were closer sisters than me and my blood sister.', 'She is mad at me and my 2 sisters.'] | G9: Family Dynamics and QAnon Influence on Sibling Relationships | H9: QAnon Influence on Family Dynamics (Sibling Relationships) | I9: 3-Oon after-Impact to others
A10: 7 | B10: 31 | C10: 618 | D10: 31_drops_believer_related_full blown | E10: ['drops', 'believer', 'related', 'full blown', 'blown', 'er', 'followers', 'anonymous', 'believers', 'discovered'] | F10: ['He is a stout Q believer.', "I look through his posts, he's full blown Q guy, Trump is the savior, the whole thing.", 'He pretty quickly became a full blown q convert and stopped going into work more and more often so he could spend more time watching youtube and talking to other fellow believers.', 'Sorry for the rant..... anyway......\n\nNot only was everyone I was watching talking about "Q Drops"...but they were also all becoming..............extremely fond of Trump.', 'he calls Q drops and the videos from top Q believers on youtube the "new Bible" and tells me to throw my copies of the "old" one away.'] | G10: QAnon Belief and Influence on Personal Lives | H10: Full-blown stage into Q?
A11: 8 | B11: 34 | C11: 569 | D11: 34_daughter_rest family_parent_side family | E11: ['daughter', 'rest family', 'parent', 'side family', 'family really', 'kid', 'grandparent', 'people family', 'son', 'sees'] | F11: ['But it kills me knowing that the rest of my family has to deal with him.', 'The rest of my family wouldn‚Äôt engage the subject at all with him.', "i don't know what to do or how to be his daughter anymore.", "I'm his daughter, his only child.", 'What do I say to demonstrate that he should put his daughter first, above all of this crap??'] | G11: Family Struggles with QAnon Beliefs | H11: QAnon Influence on Family Dynamics | I11: 3-Oon after-Impact to others
A12: 9 | B12: 35 | C12: 556 | D12: 35_boyfriend_hes_cheated_divorce | E12: ['boyfriend', 'hes', 'cheated', 'divorce', 'dare', 'agrees', 'dating', 'lets', 'ex', 'goes along'] | F12: ["It started with him threatening to dox and expose her, but then it moved to threatening to harm her, her boyfriend and even her boyfriend's cat if she didn't come back to him.", 'I don‚Äôt think he agrees with her beliefs but he just kind of lets it happen.', "Then she met her boyfriend, let's call him Dave.", '(The TL;DR of that is she had a boyfriend but cheated on that guy with my friend, but I again veer into other topics).', 'Her base for divorce was \'Hes not awake, hes part of the cabal, hes keeping secrets from me, hes gay"....'] | G12: Relationship Strain Due to QAnon Beliefs | H12: ??? | I12: 0-Background-Partner
A13: 10 | B13: 39 | C13: 523 | D13: 39_insanity_crazy one_madness_sane | E13: ['insanity', 'crazy one', 'madness', 'sane', 'sanity', 'craziness', 'like crazy', 'think crazy', 'going crazy', 'going insane'] | F13: ['I feel like I‚Äôm the crazy one.', "I don't think I have it in me to deal with any more of this insanity.", 'The man lost *everything* to this insanity.', "I'm so sick of the insanity.", 'When does this insanity end?'] | G13: Family Struggles with QAnon-Induced Insanity | H13: Family Struggles
A14: 11 | B14: 40 | C14: 523 | D14: 40_missing_saving children_protect_saving | E14: ['missing', 'saving children', 'protect', 'saving', 'safety', 'kid', 'save children', 'abuse', 'kids want', 'child abuse'] | F14: ['The estrangements were painful for these parents and in an attempt to help them process what was happening, the essay author noticed a trend of ‚Äúmissing missing reasons.‚Äù TL;DR these estranged parents almost uniformly were unable to say why they had been cut off by their adult children.', 'I am so frustrated with this "missing children" crap.', 'In many countries, statistics on missing children are not even available; and, unfortunately, even available statistics may be inaccurate due to: under-reporting/under-recognition; inflation; incorrect database entry of case information; and deletion of records once a case is closed.‚Äù \n\nand also\n\n ‚Äú250,000 children are reported missing every year in the EU, 1 child every 2 minutes‚Äù\n\ni know that the vast majority of these reported cases are custody disputes between estranged parents, but he is completely sold that these kids are legitimately abducted and trafficked, despite that being an absolutely insane number, and wouldn‚Äôt that constitute the biggest news story of our times!?', 'You thought you were saving children?', 'And where the hell are all the missing migrant children?!?!?!?!?!'] | G14: Concerns about Missing and Abducted Children | H14: Q's Belief "Save the Children" | I14: 3-Oon after-Belief
A15: 12 | B15: 42 | C15: 496 | D15: 42_relationships_strained_end relationship_repair | E15: ['relationships', 'strained', 'end relationship', 'repair', 'good relationship', 'strain relationship', 'strain', 'surface level', 'time together', 'complicated'] | F15: ['Things have been strained between the two of us since.', "In other words, it's time for me to triage my relationships.", 'I had been in several dysfunctional relationships but this was the worst.', 'Sometimes those relationships can be mended; sometimes they can‚Äôt be.', 'Suffice it to say the relationships are very strained.'] | G15: Strained Relationships Due to QAnon Involvement | I15: 3-Oon after-Social
A16: 13 | B16: 43 | C16: 493 | D16: 43_black_racist_white_racism | E16: ['black', 'racist', 'white', 'racism', 'black people', 'white people', 'race', 'brown', 'supremacy', 'color'] | F16: ['One of the things growing up that we both really struggled with was race and how having a white mother and black father was being too white for the black kids and too black for the white kids.', 'My boyfriend is black, his friend is white, and I am also white.', 'I am a black woman and my husband is a white man from the Midwest.', 'Im in a multiracial family, and often grapple with the fact that my father can be so racist when he has a black son and wife.', 'As far as racism goes everyone in the world is racist in some way.'] | G16: Interracial Relationships and Racism Experiences | I16: 0-Background-Race
A17: 14 | B17: 44 | C17: 484 | D17: 44_conversations_spoken_spoken since_communication | E17: ['conversations', 'spoken', 'spoken since', 'communication', 'end conversation', 'want talk', 'talk phone', 'talk anything', 'conversation went', 'small talk'] | F17: ['We‚Äôve had many of these conversations.', 'We were able to have real conversations.', 'Any conversations we have can be kept confidential for now.', 'We do not talk often so it never comes up in our conversations.', 'Our conversations were only about this.'] | G17: Communication Challenges in Conversations | H17: ??? | I17: ???
A18: 15 | B18: 45 | C18: 474 | D18: 45_ivermectin_horse_cure_paste | E18: ['ivermectin', 'horse', 'cure', 'paste', 'doctor', 'treat', 'doctors', 'medicine', 'doses', 'ordered'] | F18: ['and they with their buckets of ivermectin dgaf then, so why does it matter now?).', 'I have a question about ivermectin.', 'I said, "No, I won\'t be taking ivermectin.', "Ivermectin and hydroxychloroquine aren't working.", 'What effectiveness had ivermectin had anyway?'] | G18: Ivermectin Use and Skepticism in Treating Illness | I18: 3-Oon after-Belief
A19: 16 | B19: 50 | C19: 445 | D19: 50_currency_gold_silver_crypto | E19: ['currency', 'gold', 'silver', 'crypto', 'scam', 'debt', 'bank', 'dollar', 'banks', 'worthless'] | F19: ["He's been slowly funneling out our money to crypto currency that I don't have access to.", 'Thankfully he just bought gold and silver with it though.', 'My mom is spending hers and my dads life savings on crypto currency and also buying all sorts of worthless currency from EBay (Zimbabwe, Iraqi, Venezuelan currency).', 'Then somehow it turns into how we aren‚Äôt aware of what‚Äôs happening in this country and how currency is about to change to gold and silver and demanded that tomorrow he is going to buy gold!', 'He wants to put all our money into gold/silver purchases.'] | G19: Financial Decisions Influenced by Conspiracy Beliefs | I19: 3-Oon after-Behavior/action
A20: 17 | B20: 51 | C20: 443 | D20: 51_christmas_thanksgiving_holidays_holiday | E20: ['christmas', 'thanksgiving', 'holidays', 'holiday', 'celebrate', 'easter', 'eve', 'xmas', 'season', 'home christmas'] | F20: ['Christmas is just going to be different through and through.', 'I‚Äôm honestly thinking about skipping Christmas.', 'Most of my family spent Christmas day together.', 'Our Christmas traditions won‚Äôt be the same.', 'We usually spend Thanksgiving and Christmas with my family but not this year.'] | G20: Family Holiday Gatherings Affected by QAnon | I20: 3-Oon after-Impact to others
A21: 18 | B21: 52 | C21: 440 | D21: 52_step dad_told dad_step_even dad | E21: ['step dad', 'told dad', 'step', 'even dad', 'divorce', 'dad said', 'dad would', 'dad told', 'dad thinks', 'divorced'] | F21: ['She has threatened to divorce my dad after nearly 20 years of marriage because he expressed concern in her habits and behavior.', '(It at least makes me feel better that even my dad needed to see her freak out like this to realize how deep the manipulation went, and he was married to her for over 20 years before they divorced when I was in high school.', "she also said she couldnt text about it, could only talk on the phone wtf\n\ni texted my step dad saying i didn't appreciate her threatening me and to knock it off!", 'I told my dad (her son) that she hasn‚Äôt had an original thought for a long time because my step-grandpa won‚Äôt let her.', 'I am afraid she will lose my step dad.'] | G21: Family Strain Due to QAnon Beliefs | H21: (Stepdad) / manipulation | I21: 3-Oon after-Behavior/action
A22: 19 | B22: 53 | C22: 437 | D22: 53_weed_drugs_mental health_bipolar | E22: ['weed', 'drugs', 'mental health', 'bipolar', 'depression', 'addict', 'drug', 'drinking', 'schizophrenia', 'alcohol'] | F22: ["This is the same man that grew weed in our house growing up because then Government can't tell him what to do.", 'Keep in mind this person was outgoing and rebellious as a kid but growing up and after making poor decisions, from smoking weed to then more hard drugs such as meth, they‚Äôve became very different.', 'He has very strong anxiety and smokes a lot of weed.', 'Dmt, shrooms, weed, etc, should be stopped.', 'Also, he was not just on weed.'] | G22: Substance Use and Mental Health Issues | I22: 0-Background-Substance Use
A23: 20 | B23: 54 | C23: 427 | D23: 54_want kids_whole family_rest family_grandchild | E23: ['want kids', 'whole family', 'rest family', 'grandchild', 'son', 'extended family', 'see kids', 'family members', 'much family', 'contact family'] | F23: ["I swear she quotes all of the speaker's she sees I agreed with her and said I didn't want my kids to grow up with that outlook.", 'When she asked what kind of things I said things like who you want your kids to go to and medical things like a DNR.', 'She is in deep and says her whole family is as well.', "I've tried so hard to have a relationship with her for the sake of my kid, her own grandchild, because I know how much she loves him.", "She's estranged to the whole family, and I'm basically the only link I have from her to the rest of the family."] | G23: Family Estrangement Due to QAnon Beliefs | I23: 3-Oon after-Impact to others
A24: 21 | B24: 55 | C24: 412 | D24: 55_therapy_therapist_counseling_therapists | E24: ['therapy', 'therapist', 'counseling', 'therapists', 'couples', 'counselor', 'appointment', 'session', 'sessions', 'insurance'] | F24: ['And I‚Äôm still in therapy.', 'I have done the most therapy(by far).', 'I‚Äôm working on it with therapy.', "I've been through years of therapy.", 'I have recently been going to therapy to deal with these issues.'] | G24: Coping with QAnon-Related Family Strain through Therapy | I24: 3-Oon after-Impact to narr
A25: 22 | B25: 56 | C25: 405 | D25: 56_arguments_arguing_argue_argument | E25: ['arguments', 'arguing', 'argue', 'argument', 'debate', 'disagree', 'agree disagree', 'civil', 'debating', 'argued'] | F25: ["These weren't the only arguments we had about this, there was more.", "We've had these arguments already.", "We've never gotten into more arguments.", 'YOU TAKE ALL MY ARGUMENTS!', "Since then we've been fine, no arguments or anything at all."] | G25: Family Disputes Over QAnon Beliefs | H25: Family Arguments Over QAnon Beliefs | I25: 3-Oon after-Behavior/action
A26: 23 | B26: 58 | C26: 396 | D26: 58_mum_help mom_told mom_mom says | E26: ['mum', 'help mom', 'told mom', 'mom says', 'mom goes', 'get mom', 'agrees', 'mom mom', 'mom like', 'mom always'] | F26: ['Sometimes I just think about if his need for a car/help for his mom wasn‚Äôt in the picture, would he have stretched that timeframe of not wanting to be around me further?', 'I told my mom and she said he refuses to apologize since he was "tired when he said it".', 'We got passed him not wanting to see me because I am ‚Äúshedding‚Äù but a part of me believes that he only let me back in (being physically around him) because he needed help with his elderly mother (and not having car to help with his mom).', 'I am trying to help him and my mom to get into counseling for resolving there past conflict and become more open to one another.', 'He needed help with mom.'] | G26: Family Dynamics and Support Involving Mom | H26: ??? | I26: ???
A27: 24 | B27: 59 | C27: 394 | D27: 59_miss_love much_still love_feel bad | E27: ['miss', 'love much', 'still love', 'feel bad', 'senses', 'loves', 'want relationship', 'person used', 'come back', 'get back'] | F27: ['I want him to miss me too.', 'I miss him more than anything.', 'I just miss him so very, very much!', 'I miss him so much.', 'I just miss him and wish it wasn‚Äôt like this.'] | G27: Missing Loved Ones Due to QAnon Involvement | I27: 3-Oon after-Impact to narr
A28: 25 | B28: 60 | C28: 394 | D28: 60_cried_cry_crying_tears | E28: ['cried', 'cry', 'crying', 'tears', 'scream', 'sobbing', 'laugh', 'void', 'eyes', 'broke'] | F28: ['I cried because of how happy I was.', 'I cried so much already.', 'Maybe I cried all I could that day in the barn.', 'I cried, I was angry, I had so much sorrow, and I grieved.', 'I have cried so many tears and am on anti depressants to help me out.'] | G28: Emotional Distress and Coping | I28: 3-Oon after-Impact to narr
A29: 26 | B29: 64 | C29: 363 | D29: 64_older brother_brothers_older_younger brother | E29: ['older brother', 'brothers', 'older', 'younger brother', 'brother said', 'like brother', 'little brother', 'younger', 'brother told', 'lose'] | F29: ['My older brother has always walked on water in my eyes.', "I MISS MY OLDER BROTHER WHO I WISHED TO BE AS COOL AS GROWING UP BUT NOW I DON'T EVEN RECOGNIZE YOU.", 'My brothers are the same.', 'Both of my brothers have done this, it‚Äôs my turn.', 'My older brother was so special to us (lost him \\~7 years ago).'] | G29: Family Strain Due to QAnon Beliefs | H29: (Narrator-oon) Relationship with Brother? | I29: 0-Background-Relationship with narr
A30: 27 | B30: 66 | C30: 353 | D30: 66_twitter_facebook_fb_banned | E30: ['twitter', 'facebook', 'fb', 'banned', 'social media', 'account', 'https twitter', 'https twitter com', 'twitter com', 'instagram'] | F30: ['The best way to keep up on happenings is with these Twitter accounts:\n\n&#x200B;\n\n[https://twitter.com/fr\\_brennan](https://twitter.com/fr_brennan)\n\n[https://twitter.com/Kirtaner](https://twitter.com/Kirtaner)\n\n[https://twitter.com/AJVicens](https://twitter.com/AJVicens)\n\n[https://twitter.com/alibreland](https://twitter.com/alibreland)\n\n[https://twitter.com/AmericanHacker](https://twitter.com/AmericanHacker)\n\n[https://twitter.com/FoucaultMotoko](https://twitter.com/FoucaultMotoko)', 'He‚Äôs more active on twitter than fb.', "I looked down at my phone for something and saw the announcement that Trump's twitter account had been banned.", 'His Twitter account got banned a day before trump‚Äôs did.', 'I ask him to give up twitter (for a few days) and he can‚Äôt do that.'] | G30: Social Media and QAnon Involvement | I30: 2-Trigger-Social Media
A31: 28 | B31: 69 | C31: 345 | D31: 69_boundaries_bring back_like lost_want back | E31: ['boundaries', 'bring back', 'like lost', 'want back', 'breaks heart', 'feel like lost', 'want lose', 'breaks', 'get back', 'love much'] | F31: ['I feel like I lost her.', 'I feel like I lost her.', "I feel like she's lost to me.", 'he backed me up in my boundaries because he also has those boundaries with her, And is definitely the only reason why she is adhering to those boundaries right now.', 'She won‚Äôt adhere to my boundaries.'] | G31: Family Strain Due to QAnon Beliefs | I31: 3-Oon after-Impact to narr | J31: Narr's feeling
A32: 30 | B32: 73 | C32: 329 | D32: 73_youtube_algorithm_podcast_youtube videos | E32: ['youtube', 'algorithm', 'podcast', 'youtube videos', 'channel', 'algorithms', 'youtube com', 'youtube video', 'https', 'videos articles'] | F32: [' \n\nHello everyone,\n\nmy Name is Adrian and I am a journalist, working for the german television broadcast SPIEGEL TV MAGAZIN (Our YT-Channel: [https://www.youtube.com/user/spiegeltv](https://www.youtube.com/user/spiegeltv)).', 'Another interesting video I found on youtube is this one: [https://www.youtube.com/watch?v=NPHwO\\_sVSAQ](https://www.youtube.com/watch?v=NPHwO_sVSAQ).', 'I didn‚Äôt click on the YouTube video he sent because I didn‚Äôt want the algorithm to think I was interested in that.', 'But a lot comes from YouTube.', 'His youtube algorithm is nothing but this stuff.'] | G32: Impact of YouTube Algorithms on QAnon Content Consumption | I32: 2-Trigger-Social Media
A33: 31 | B33: 74 | C33: 327 | D33: 74_grief_grieving_mourning_grieve | E33: ['grief', 'grieving', 'mourning', 'grieve', 'betrayed', 'loss', 'like mourning', 'still alive', 'mourn', 'alive'] | F33: ['I felt the grief again.', "It feels like I'm grieving for someone who is still alive.", 'It feels like grieving a loss.', 'We are literally grieving the loss of our loved ones while they are still alive.', "I've honestly felt grief at the loss."] | G33: Grieving the Living | I33: 3-Oon after-Impact to narr
A34: 32 | B34: 78 | C34: 311 | D34: 78_pandemic_pandemic started_pandemic hit_since pandemic | E34: ['pandemic', 'pandemic started', 'pandemic hit', 'since pandemic', 'start pandemic', 'hit', 'pandemic really', 'pandemic began', 'beginning pandemic', 'got worse'] | F34: ["I'm frigging sick of this pandemic.", 'I hate what this pandemic has done to my kids‚Äô lives.', 'And then the pandemic happened.', "With the pandemic, it's been worse.", 'All well before the pandemic.'] | G34: Impact of the Pandemic on Personal Lives | I34: 2-Trigger-Pandemic
A35: 33 | B35: 81 | C35: 307 | D35: 81_baby_pregnant_pregnancy_first child | E35: ['baby', 'pregnant', 'pregnancy', 'first child', 'newborn', 'birth', 'born', 'expecting', 'grandchild', 'daughter'] | F35: ['How does anyone do this to their baby?!', 'We are having a baby soon.', "I kissed my baby's forehead and left.", 'I was just worried about my baby.', "Or, let's make love and make a baby."] | G35: Family and Pregnancy Concerns in QAnon Context | I35: 0-Background-Family
A36: 34 | B36: 83 | C36: 303 | D36: 83_retirement_lost job_fired_business | E36: ['retirement', 'lost job', 'fired', 'business', 'company', 'works', 'get job', 'retired', 'jobs', 'unemployed'] | F36: ['He hasnt lost his job yet, but it may happen.', 'Once he got to the U.S he worked a few odd jobs and started his own business.', 'They are maxed again and he is running out of retirement.', "He's a man nearing retirement age with a family.", 'He, the fucker, who‚Äôs close to retirement age anyway.'] | G36: Impact of QAnon on Employment and Retirement | H36: Impact of QAnon on | I36: 0-Background-Job
A37: 35 | B37: 86 | C37: 295 | D37: 86_sources_article_articles_source | E37: ['sources', 'article', 'articles', 'source', 'credible', 'reliable', 'proof', 'send', 'fake news', 'google'] | F37: ["I've sent her so many sources counteracting her and my uncle's claims.", 'I easily found multiple articles for each of her sources that debunked the information claimed and showed why these sources were not credible.', 'I asked her what sources she would trust.', 'I ask for sources and there is never any real source to back up the claims, but I "have to understand, she is getting this information from credible sources."', 'She won\'t listen to any fact, only these "sources".'] | G37: Credibility of Information Sources | H37: Q's unsourced belief? | I37: 3-Oon after-Behavior/action
A38: 36 | B38: 91 | C38: 279 | D38: 91_gates_bill gates_bill_5g | E38: ['gates', 'bill gates', 'bill', '5g', 'microchips', 'microchip', 'dna', 'vaccines', 'kill', 'population'] | F38: ['* Bill Gates - eugenics, decreasing the population, and vaccines\n* Globalism/NWO - George Soros, the Rockefellers, Jeff Bezos, Bill Gates, Klaus Schwabb, etc.', "And it was Bill Gates' company.", 'And of course the 5G, Covid, and Bill Gates conspiracies make sense to them.', 'Bill Gates is trying to implant microchips.', "I honestly still don't understand the Bill Gates thing."] | G38: Bill Gates and Conspiracy Theories | I38: 3-Oon after-Belief
A39: 37 | B39: 92 | C39: 276 | D39: 92_red_texas_florida_area | E39: ['red', 'texas', 'florida', 'area', 'rural', 'town', 'county', 'city', 'states', 'blue'] | F39: ['We live in a red state.', "We're also in a red state.", 'Still, he is deep in a red state.', 'We are from a very small rural red town.', 'I live in a very red area.'] | G39: Impact of QAnon in Conservative Rural Areas | H39: Demographics (red state) | I39: 0-Background-Political region
A40: 38 | B40: 99 | C40: 258 | D40: 99_racist_white_black_black people | E40: ['racist', 'white', 'black', 'black people', 'racism', 'race', 'racial', 'white supremacists', 'supremacists', 'white people'] | F40: ['He told me not to be racist.', 'That Trump is not now, nor has he ever been racist.', 'He is racist and he knows it.', 'It made him more racist.', 'He‚Äôs been doing this and making racist stereotypes.'] | G40: Racism and Racial Attitudes in QAnon Narratives | I40: 3-Oon after-Behavior/action
...

Sheet prelim_categories
A1: {=_xlfn._xlws.SORT(_xlfn.UNIQUE(topics_merged!I3:I264))} -> ??? | C1: =COUNTIF(topics_merged!I$3:I$264, A1) -> 15
A2: 0-Background-Addiction | C2: =COUNTIF(topics_merged!I$3:I$264, A2) -> 1 | D2: =SUM(C2:C21) -> 30
A3: 0-Background-Age | C3: =COUNTIF(topics_merged!I$3:I$264, A3) -> 1
A4: 0-Background-Closeness | C4: =COUNTIF(topics_merged!I$3:I$264, A4) -> 1
A5: 0-Background-Education | C5: =COUNTIF(topics_merged!I$3:I$264, A5) -> 1
A6: 0-Background-Family | C6: =COUNTIF(topics_merged!I$3:I$264, A6) -> 3
A7: 0-Background-Generation | C7: =COUNTIF(topics_merged!I$3:I$264, A7) -> 1
A8: 0-Background-Geography | C8: =COUNTIF(topics_merged!I$3:I$264, A8) -> 2
A9: 0-Background-Health | C9: =COUNTIF(topics_merged!I$3:I$264, A9) -> 2
A10: 0-Background-Housing | C10: =COUNTIF(topics_merged!I$3:I$264, A10) -> 1
A11: 0-Background-Ideology | C11: =COUNTIF(topics_merged!I$3:I$264, A11) -> 2
A12: 0-Background-Job | C12: =COUNTIF(topics_merged!I$3:I$264, A12) -> 1
A13: 0-Background-Living condition | C13: =COUNTIF(topics_merged!I$3:I$264, A13) -> 1
A14: 0-Background-Mental State | C14: =COUNTIF(topics_merged!I$3:I$264, A14) -> 1
... A21: 0-Background-Substance Use | C21: =COUNTIF(topics_merged!I$3:I$264, A21) -> 1
A22: 1-Oon before-Personality | C22: =COUNTIF(topics_merged!I$3:I$264, A22) -> 2 | D22: 2
A23: 2-Trigger-Alt news | C23: =COUNTIF(topics_merged!I$3:I$264, A23) -> 1 | D23: =SUM(C23:C29) -> 16
A24: 2-Trigger-Election | C24: =COUNTIF(topics_merged!I$3:I$264, A24) -> 1
A25: 2-Trigger-Influencers | C25: =COUNTIF(topics_merged!I$3:I$264, A25) -> 2
A26: 2-Trigger-Lockdown | C26: =COUNTIF(topics_merged!I$3:I$264, A26) -> 1
A27: 2-Trigger-Pandemic | C27: =COUNTIF(topics_merged!I$3:I$264, A27) -> 3
A28: 2-Trigger-Religion | C28: =COUNTIF(topics_merged!I$3:I$264, A28) -> 1
A29: 2-Trigger-Social Media | C29: =COUNTIF(topics_merged!I$3:I$264, A29) -> 7
A30: 3-Oon after-Behavior/action | B30: Behavior or Action of Object of Narration i.e Q person (things that they actually do/did) | C30: =COUNTIF(topics_merged!I$3:I$264, A30) -> 45 | D30: =SUM(C30:C38) -> 156
A31: 3-Oon after-Belief | B31: Beliefs of Object of Narration i.e Q person (things that they believe in, not necessary enforce(?) themselves) | C31: =COUNTIF(topics_merged!I$3:I$264, A31) -> 47
A32: 3-Oon after-Family | C32: =COUNTIF(topics_merged!I$3:I$264, A32) -> 1
A33: 3-Oon after-Impact to narr | C33: =COUNTIF(topics_merged!I$3:I$264, A33) -> 35
A34: 3-Oon after-Impact to others | C34: =COUNTIF(topics_merged!I$3:I$264, A34) -> 9
A35: 3-Oon after-Job | C35: =COUNTIF(topics_merged!I$3:I$264, A35) -> 1
A36: 3-Oon after-Legal | C36: =COUNTIF(topics_merged!I$3:I$264, A36) -> 1
A37: 3-Oon after-Social | C37: =COUNTIF(topics_merged!I$3:I$264, A37) -> 14
A38: 3-Oon after-State | C38: =COUNTIF(topics_merged!I$3:I$264, A38) -> 3
A39: 0 | C39: =COUNTIF(topics_merged!I41:I302, A39) -> 0

Sheet random_sample
B1: Topic | C1: Count | D1: Name | E1: Representation | F1: Representative_Docs | G1: GPT Label | H1: Better Label? | I1: Category (0 - Background, 1 - Oon before, 2 - Trigger, 3 - Oon after)
A2: 7 | B2: 31 | C2: 618 | D2: 31_drops_believer_related_full blown | E2: ['drops', 'believer', 'related', 'full blown', 'blown', 'er', 'followers', 'anonymous', 'believers', 'discovered'] | F2: ['He is a stout Q believer.', "I look through his posts, he's full blown Q guy, Trump is the savior, the whole thing.", 'He pretty quickly became a full blown q convert and stopped going into work more and more often so he could spend more time watching youtube and talking to other fellow believers.', 'Sorry for the rant..... anyway......\n\nNot only was everyone I was watching talking about "Q Drops"...but they were also all becoming..............extremely fond of Trump.', 'he calls Q drops and the videos from top Q believers on youtube the "new Bible" and tells me to throw my copies of the "old" one away.'] | G2: QAnon Belief and Influence on Personal Lives | H2: Full-blown stage into Q?
A3: 10 | B3: 39 | C3: 523 | D3: 39_insanity_crazy one_madness_sane | E3: ['insanity', 'crazy one', 'madness', 'sane', 'sanity', 'craziness', 'like crazy', 'think crazy', 'going crazy', 'going insane'] | F3: ['I feel like I‚Äôm the crazy one.', "I don't think I have it in me to deal with any more of this insanity.", 'The man lost *everything* to this insanity.', "I'm so sick of the insanity.", 'When does this insanity end?'] | G3: Family Struggles with QAnon-Induced Insanity | H3: Family Struggles with
A4: 26 | B4: 64 | C4: 363 | D4: 64_older brother_brothers_older_younger brother | E4: ['older brother', 'brothers', 'older', 'younger brother', 'brother said', 'like brother', 'little brother', 'younger', 'brother told', 'lose'] | F4: ['My older brother has always walked on water in my eyes.', "I MISS MY OLDER BROTHER WHO I WISHED TO BE AS COOL AS GROWING UP BUT NOW I DON'T EVEN RECOGNIZE YOU.", 'My brothers are the same.', 'Both of my brothers have done this, it‚Äôs my turn.', 'My older brother was so special to us (lost him \\~7 years ago).'] | G4: Family Strain Due to QAnon Beliefs | H4: [Oon-Narrator) Relationship - Brother | I4: 0-Background-Relationship with narr
A5: 37 | B5: 92 | C5: 276 | D5: 92_red_texas_florida_area | E5: ['red', 'texas', 'florida', 'area', 'rural', 'town', 'county', 'city', 'states', 'blue'] | F5: ['We live in a red state.', "We're also in a red state.", 'Still, he is deep in a red state.', 'We are from a very small rural red town.', 'I live in a very red area.'] | G5: Impact of QAnon in Conservative Rural Areas | H5: Demographics (red state) | I5: 0-Background-Political region
A6: 47 | B6: 114 | C6: 226 | D6: 114_siblings_cousin_cousins_sibling | E6: ['siblings', 'cousin', 'cousins', 'sibling', 'aunts', 'uncle', 'older', 'aunt', 'aunt uncle', 'brothers'] | F6: ['I have many other siblings.', 'And I‚Äôm their only child, no siblings.', "Me and my siblings don't know what to do.", 'I just sorry for my siblings', 'My cousins were like siblings.'] | G6: Family Relationships and QAnon Impact | H6: [Oon-Narrator) Relationship - Siblings | I6: 0-Background-Relationship with narr
